[32mâœ“[0m Connected to cloud
2024-09-03 11:53:01,017 - INFO - Location: [32mSan Fransisco[0m, Day: [35m0[0m, Check digits: [36m585362[0m
Traceback (most recent call last):
  File "/home/ec2-user/.local/lib/python3.7/site-packages/urllib3/connection.py", line 175, in _new_conn
    (self._dns_host, self.port), self.timeout, **extra_kw
  File "/home/ec2-user/.local/lib/python3.7/site-packages/urllib3/util/connection.py", line 95, in create_connection
    raise err
  File "/home/ec2-user/.local/lib/python3.7/site-packages/urllib3/util/connection.py", line 85, in create_connection
    sock.connect(sa)
TimeoutError: [Errno 110] Connection timed out

During handling of the above exception, another exception occurred:

Traceback (most recent call last):
  File "/home/ec2-user/.local/lib/python3.7/site-packages/urllib3/connectionpool.py", line 710, in urlopen
    chunked=chunked,
  File "/home/ec2-user/.local/lib/python3.7/site-packages/urllib3/connectionpool.py", line 398, in _make_request
    conn.request(method, url, **httplib_request_kw)
  File "/home/ec2-user/.local/lib/python3.7/site-packages/urllib3/connection.py", line 239, in request
    super(HTTPConnection, self).request(method, url, body=body, headers=headers)
  File "/usr/lib64/python3.7/http/client.py", line 1277, in request
    self._send_request(method, url, body, headers, encode_chunked)
  File "/usr/lib64/python3.7/http/client.py", line 1323, in _send_request
    self.endheaders(body, encode_chunked=encode_chunked)
  File "/usr/lib64/python3.7/http/client.py", line 1272, in endheaders
    self._send_output(message_body, encode_chunked=encode_chunked)
  File "/usr/lib64/python3.7/http/client.py", line 1032, in _send_output
    self.send(msg)
  File "/usr/lib64/python3.7/http/client.py", line 972, in send
    self.connect()
  File "/home/ec2-user/.local/lib/python3.7/site-packages/urllib3/connection.py", line 205, in connect
    conn = self._new_conn()
  File "/home/ec2-user/.local/lib/python3.7/site-packages/urllib3/connection.py", line 187, in _new_conn
    self, "Failed to establish a new connection: %s" % e
urllib3.exceptions.NewConnectionError: <urllib3.connection.HTTPConnection object at 0x7f3ceac7de50>: Failed to establish a new connection: [Errno 110] Connection timed out

During handling of the above exception, another exception occurred:

Traceback (most recent call last):
  File "/home/ec2-user/.local/lib/python3.7/site-packages/requests/adapters.py", line 499, in send
    timeout=timeout,
  File "/home/ec2-user/.local/lib/python3.7/site-packages/urllib3/connectionpool.py", line 786, in urlopen
    method, url, error=e, _pool=self, _stacktrace=sys.exc_info()[2]
  File "/home/ec2-user/.local/lib/python3.7/site-packages/urllib3/util/retry.py", line 592, in increment
    raise MaxRetryError(_pool, url, error or ResponseError(cause))
urllib3.exceptions.MaxRetryError: HTTPConnectionPool(host='wttr.in', port=80): Max retries exceeded with url: /San%20Fransisco?format=j1 (Caused by NewConnectionError('<urllib3.connection.HTTPConnection object at 0x7f3ceac7de50>: Failed to establish a new connection: [Errno 110] Connection timed out'))

During handling of the above exception, another exception occurred:

Traceback (most recent call last):
  File "weather.py", line 177, in <module>
    cwdata, code = currentweather(location, checkdigits)
  File "weather.py", line 55, in currentweather
    data, code = weather(location)
  File "weather.py", line 41, in weather
    response = requests.get(url)
  File "/home/ec2-user/.local/lib/python3.7/site-packages/requests/api.py", line 73, in get
    return request("get", url, params=params, **kwargs)
  File "/home/ec2-user/.local/lib/python3.7/site-packages/requests/api.py", line 59, in request
    return session.request(method=method, url=url, **kwargs)
  File "/home/ec2-user/.local/lib/python3.7/site-packages/requests/sessions.py", line 587, in request
    resp = self.send(prep, **send_kwargs)
  File "/home/ec2-user/.local/lib/python3.7/site-packages/requests/sessions.py", line 701, in send
    r = adapter.send(request, **kwargs)
  File "/home/ec2-user/.local/lib/python3.7/site-packages/requests/adapters.py", line 565, in send
    raise ConnectionError(e, request=request)
requests.exceptions.ConnectionError: HTTPConnectionPool(host='wttr.in', port=80): Max retries exceeded with url: /San%20Fransisco?format=j1 (Caused by NewConnectionError('<urllib3.connection.HTTPConnection object at 0x7f3ceac7de50>: Failed to establish a new connection: [Errno 110] Connection timed out'))
