Traceback (most recent call last):
  File "/home/ec2-user/.local/lib/python3.7/site-packages/scratchattach/cloud.py", line 82, in _connect
    timeout=self._ws_timeout
  File "/home/ec2-user/.local/lib/python3.7/site-packages/websocket/_core.py", line 248, in connect
    self.handshake_response = handshake(self.sock, url, *addrs, **options)
  File "/home/ec2-user/.local/lib/python3.7/site-packages/websocket/_handshake.py", line 57, in handshake
    status, resp = _get_resp_headers(sock)
  File "/home/ec2-user/.local/lib/python3.7/site-packages/websocket/_handshake.py", line 148, in _get_resp_headers
    raise WebSocketBadStatusException("Handshake status %d %s", status, status_message, resp_headers)
websocket._exceptions.WebSocketBadStatusException: Handshake status 504 Gateway Time-out

During handling of the above exception, another exception occurred:

Traceback (most recent call last):
  File "/home/ec2-user/.local/lib/python3.7/site-packages/scratchattach/cloud.py", line 92, in _connect
    timeout=self._ws_timeout
  File "/home/ec2-user/.local/lib/python3.7/site-packages/websocket/_core.py", line 248, in connect
    self.handshake_response = handshake(self.sock, url, *addrs, **options)
  File "/home/ec2-user/.local/lib/python3.7/site-packages/websocket/_handshake.py", line 57, in handshake
    status, resp = _get_resp_headers(sock)
  File "/home/ec2-user/.local/lib/python3.7/site-packages/websocket/_handshake.py", line 148, in _get_resp_headers
    raise WebSocketBadStatusException("Handshake status %d %s", status, status_message, resp_headers)
websocket._exceptions.WebSocketBadStatusException: Handshake status 504 Gateway Time-out

During handling of the above exception, another exception occurred:

Traceback (most recent call last):
  File "weather.py", line 14, in <module>
    conn = session.connect_cloud("830536684")
  File "/home/ec2-user/.local/lib/python3.7/site-packages/scratchattach/session.py", line 363, in connect_cloud
    return cloud.CloudConnection(username = self._username, session_id = self.session_id, project_id = int(project_id))
  File "/home/ec2-user/.local/lib/python3.7/site-packages/scratchattach/cloud.py", line 27, in __init__
    self._connect(cloud_host=cloud_host)
  File "/home/ec2-user/.local/lib/python3.7/site-packages/scratchattach/cloud.py", line 95, in _connect
    raise(exceptions.ConnectionError)
scratchattach.exceptions.ConnectionError
