[32mâœ“[0m Connected to cloud
2024-05-09 06:01:40,891 - INFO - Location: [32mSFO[0m, Day: [35m0[0m, Check digits: [36m813958[0m
2024-05-09 06:01:48,186 - INFO - Location: [32mSFO[0m, Day: [35m0[0m, Check digits: [36m192475[0m
2024-05-09 06:02:04,143 - INFO - Location: [32mSFO[0m, Day: [35m0[0m, Check digits: [36m442290[0m
2024-05-09 06:02:19,961 - INFO - Location: [32mSFO[0m, Day: [35m0[0m, Check digits: [36m888444[0m
2024-05-09 06:02:57,092 - INFO - Location: [32mSFO[0m, Day: [35m1[0m, Check digits: [36m747026[0m
2024-05-09 06:03:03,786 - INFO - Location: [32mKillen[0m, Day: [35m0[0m, Check digits: [36m155486[0m
Traceback (most recent call last):
  File "/home/ec2-user/.local/lib/python3.7/site-packages/requests/models.py", line 971, in json
    return complexjson.loads(self.text, **kwargs)
  File "/usr/lib64/python3.7/site-packages/simplejson/__init__.py", line 488, in loads
    return _default_decoder.decode(s)
  File "/usr/lib64/python3.7/site-packages/simplejson/decoder.py", line 374, in decode
    obj, end = self.raw_decode(s)
  File "/usr/lib64/python3.7/site-packages/simplejson/decoder.py", line 393, in raw_decode
    return self.scan_once(s, idx=_w(s, idx).end())
simplejson.scanner.JSONDecodeError: Expecting value: line 1 column 1 (char 0)

During handling of the above exception, another exception occurred:

Traceback (most recent call last):
  File "weather.py", line 177, in <module>
    cwdata, code = currentweather(location, checkdigits)
  File "weather.py", line 55, in currentweather
    data, code = weather(location)
  File "weather.py", line 42, in weather
    json = response.json()
  File "/home/ec2-user/.local/lib/python3.7/site-packages/requests/models.py", line 975, in json
    raise RequestsJSONDecodeError(e.msg, e.doc, e.pos)
requests.exceptions.JSONDecodeError: Expecting value: line 1 column 1 (char 0)
