[32mâœ“[0m Connected to cloud
2024-09-04 14:41:42,306 - INFO - Location: [32mDetroit, mi[0m, Day: [35m0[0m, Check digits: [36m811920[0m
2024-09-05 13:34:47,683 - INFO - Location: [32mNashville[0m, Day: [35m0[0m, Check digits: [36m968822[0m
2024-09-05 13:35:01,424 - INFO - Location: [32mNashville[0m, Day: [35m1[0m, Check digits: [36m421541[0m
2024-09-05 13:35:15,778 - INFO - Location: [32mNashville[0m, Day: [35m0[0m, Check digits: [36m987859[0m
2024-09-05 13:35:38,778 - INFO - Location: [32mBaxter[0m, Day: [35m0[0m, Check digits: [36m882813[0m
2024-09-05 13:36:00,925 - INFO - Location: [32mBaxter, Tennessee[0m, Day: [35m0[0m, Check digits: [36m237073[0m
Traceback (most recent call last):
  File "/home/ec2-user/.local/lib/python3.7/site-packages/requests/models.py", line 971, in json
    return complexjson.loads(self.text, **kwargs)
  File "/usr/lib64/python3.7/site-packages/simplejson/__init__.py", line 488, in loads
    return _default_decoder.decode(s)
  File "/usr/lib64/python3.7/site-packages/simplejson/decoder.py", line 374, in decode
    obj, end = self.raw_decode(s)
  File "/usr/lib64/python3.7/site-packages/simplejson/decoder.py", line 393, in raw_decode
    return self.scan_once(s, idx=_w(s, idx).end())
simplejson.scanner.JSONDecodeError: Expecting value: line 1 column 1 (char 0)

During handling of the above exception, another exception occurred:

Traceback (most recent call last):
  File "weather.py", line 177, in <module>
    cwdata, code = currentweather(location, checkdigits)
  File "weather.py", line 55, in currentweather
    data, code = weather(location)
  File "weather.py", line 42, in weather
    json = response.json()
  File "/home/ec2-user/.local/lib/python3.7/site-packages/requests/models.py", line 975, in json
    raise RequestsJSONDecodeError(e.msg, e.doc, e.pos)
requests.exceptions.JSONDecodeError: Expecting value: line 1 column 1 (char 0)
