[32mâœ“[0m Connected to cloud
2024-05-05 23:21:25,001 - INFO - Location: [32mSan Jose[0m, Day: [35m0[0m, Check digits: [36m435134[0m
2024-05-05 23:21:59,517 - INFO - Location: [32mSan Jose[0m, Day: [35m1[0m, Check digits: [36m257983[0m
2024-05-05 23:28:13,205 - INFO - Location: [32mToulouse[0m, Day: [35m0[0m, Check digits: [36m750701[0m
2024-05-05 23:28:28,898 - INFO - Location: [32mToulouse[0m, Day: [35m0[0m, Check digits: [36m949030[0m
2024-05-05 23:31:00,272 - INFO - Location: [32m yyyyyyyyyyj\qqqqqqqqqqqqqqqqqqqqqqqqqqqqqqqqqqqqqqqqqqqqqqgvfe7[0m, Day: [35m0[0m, Check digits: [36m161466[0m
Traceback (most recent call last):
  File "/home/ec2-user/.local/lib/python3.7/site-packages/requests/models.py", line 971, in json
    return complexjson.loads(self.text, **kwargs)
  File "/usr/lib64/python3.7/site-packages/simplejson/__init__.py", line 488, in loads
    return _default_decoder.decode(s)
  File "/usr/lib64/python3.7/site-packages/simplejson/decoder.py", line 374, in decode
    obj, end = self.raw_decode(s)
  File "/usr/lib64/python3.7/site-packages/simplejson/decoder.py", line 393, in raw_decode
    return self.scan_once(s, idx=_w(s, idx).end())
simplejson.scanner.JSONDecodeError: Expecting value: line 1 column 1 (char 0)

During handling of the above exception, another exception occurred:

Traceback (most recent call last):
  File "weather.py", line 177, in <module>
    cwdata, code = currentweather(location, checkdigits)
  File "weather.py", line 55, in currentweather
    data, code = weather(location)
  File "weather.py", line 42, in weather
    json = response.json()
  File "/home/ec2-user/.local/lib/python3.7/site-packages/requests/models.py", line 975, in json
    raise RequestsJSONDecodeError(e.msg, e.doc, e.pos)
requests.exceptions.JSONDecodeError: Expecting value: line 1 column 1 (char 0)
